<?xml version="1.0" ?>
<!-- =================================================================================== -->
<!-- |    This document was autogenerated by xacro from kr20.xacro                     | -->
<!-- |    EDITING THIS FILE BY HAND IS NOT RECOMMENDED                                 | -->
<!-- =================================================================================== -->
<robot name="myrobot">
  <!-- END - Include -->
  <!-- World frame (for Gazebo) -->
  <link name="world"/>
  <!-- Arm fixed to world frame  -->
  <joint name="world__base" type="fixed">
    <parent link="world"/>
    <child link="base_link"/>
    <origin rpy="0 0 0" xyz="0 0 0"/>
  </joint>
  <link name="base_link">
    <inertial>
      <mass value="414.0"/>
      <origin rpy="0 0 0" xyz="0 0 0"/>
      <inertia ixx="97670000" ixy="0" ixz="0" iyy="97670000" iyz="0" izz="2170000"/>
    </inertial>
    <collision>
      <origin rpy="0 0 0" xyz="0 0 0"/>
      <geometry>
        <mesh filename="package://universal_robot/meshes/base_link.stl" scale="0.001 0.001 0.001"/>
      </geometry>
    </collision>
    <visual>
      <origin rpy="0 0 0" xyz="0 0 0"/>
      <geometry>
        <mesh filename="package://universal_robot/meshes/base_link.stl" scale="0.001 0.001 0.001"/>
      </geometry>
      <material name="Grey"/>
    </visual>
  </link>
  <material name="DarkGreen">
    <color rgba="0 0.36 0.012 1.0"/>
  </material>
  <material name="LightGreen">
    <color rgba="0.82 0.95 0.82 1.0"/>
  </material>
  <material name="Orange">
    <color rgba="1.0 0.5 0.0 1.0"/>
  </material>
  <material name="White">
    <color rgba="0.96 0.96 0.96 1.0"/>
  </material>
  <material name="Grey">
    <color rgba="0.56 0.56 0.56 1.0"/>
  </material>
  <gazebo reference="base">
    <material>Gazebo/Grey</material>
  </gazebo>
  <gazebo reference="link01">
    <material>Gazebo/Grey</material>
  </gazebo>
  <gazebo reference="link02">
    <material>Gazebo/Orange</material>
  </gazebo>
  <gazebo reference="link03">
    <material>Gazebo/Orange</material>
  </gazebo>
  <gazebo reference="link04">
    <material>Gazebo/Orange</material>
  </gazebo>
  <gazebo reference="link05">
    <material>Gazebo/Orange</material>
  </gazebo>
  <gazebo reference="link06">
    <material>Gazebo/Orange</material>
  </gazebo>
  <gazebo reference="link07">
    <material>Gazebo/Orange</material>
  </gazebo>
  <gazebo reference="linkef">
    <material>Gazebo/Grey</material>
  </gazebo>
  <!-- BEGIN - Robot description -->
  <joint name="q1" type="revolute">
    <axis xyz="0 0 1"/>
    <limit effort="1000" lower="-3.14" upper="3.14" velocity="0.5"/>
    <origin rpy="0 0 0" xyz="0 0 0.12"/>
    <parent link="base_link"/>
    <child link="link01"/>
  </joint>
  <transmission name="trans_q1">
    <type>transmission_interface/SimpleTransmission</type>
    <joint name="q1">
      <hardwareInterface>hardware_interface/PositionJointInterface</hardwareInterface>
    </joint>
    <actuator name="motor_q1">
      <hardwareInterface>hardware_interface/PositionJointInterface</hardwareInterface>
      <mechanicalReduction>100</mechanicalReduction>
    </actuator>
  </transmission>
  <link name="link01">
    <inertial>
      <mass value="24.74"/>
      <origin rpy="0 0 0" xyz="0 0 0"/>
      <inertia ixx="1430" ixy="84.25" ixz="0.2969" iyy="82.08" iyz="-1.64" izz="1405"/>
    </inertial>
    <collision>
      <origin rpy="0 0 0" xyz="0 0 0"/>
      <geometry>
        <mesh filename="package://universal_robot/meshes/Link1.stl" scale="0.001 0.001 0.001"/>
      </geometry>
    </collision>
    <visual>
      <origin rpy="0 0 0" xyz="0 0 0"/>
      <geometry>
        <mesh filename="package://universal_robot/meshes/Link1.stl" scale="0.001 0.001 0.001"/>
      </geometry>
      <material name="Grey"/>
    </visual>
  </link>
  <joint name="q2" type="prismatic">
    <axis xyz="0 1 0"/>
    <limit effort="1000" lower="-0.192" upper="0.216" velocity="0.5"/>
    <origin rpy="0 0 0" xyz="0 0.37775 0.089"/>
    <parent link="link01"/>
    <child link="link02"/>
  </joint>
  <transmission name="trans_q2">
    <type>transmission_interface/SimpleTransmission</type>
    <joint name="q2">
      <hardwareInterface>hardware_interface/PositionJointInterface</hardwareInterface>
    </joint>
    <actuator name="motor_q2">
      <hardwareInterface>hardware_interface/PositionJointInterface</hardwareInterface>
      <mechanicalReduction>100</mechanicalReduction>
    </actuator>
  </transmission>
  <link name="link02">
    <inertial>
      <mass value="10.88"/>
      <origin rpy="0 0 0" xyz="0 0 0"/>
      <inertia ixx="67.73" ixy="1.2" ixz="0.184" iyy="59.85" iyz="-0.005" izz="83.55"/>
    </inertial>
    <collision>
      <origin rpy="0 0 0" xyz="0 0 0"/>
      <geometry>
        <mesh filename="package://universal_robot/meshes/Link2.stl" scale="0.001 0.001 0.001"/>
      </geometry>
    </collision>
    <visual>
      <origin rpy="0 0 0" xyz="0 0 0"/>
      <geometry>
        <mesh filename="package://universal_robot/meshes/Link2.stl" scale="0.001 0.001 0.001"/>
      </geometry>
      <material name="Orange"/>
    </visual>
  </link>
  <joint name="q3" type="revolute">
    <axis xyz="0 1 0"/>
    <limit effort="1000" lower="-2.15" upper="2.15" velocity="0.5"/>
    <origin rpy="0 0 0" xyz="0.115 0.11 0"/>
    <parent link="link02"/>
    <child link="link03"/>
  </joint>
  <transmission name="trans_q3">
    <type>transmission_interface/SimpleTransmission</type>
    <joint name="q3">
      <hardwareInterface>hardware_interface/PositionJointInterface</hardwareInterface>
    </joint>
    <actuator name="motor_q3">
      <hardwareInterface>hardware_interface/PositionJointInterface</hardwareInterface>
      <mechanicalReduction>100</mechanicalReduction>
    </actuator>
  </transmission>
  <link name="link03">
    <inertial>
      <mass value="19.26"/>
      <origin rpy="0 0 0" xyz="0 0 0"/>
      <inertia ixx="56.06" ixy="-4.0" ixz="0" iyy="1396.0" iyz="0" izz="1404.0"/>
    </inertial>
    <collision>
      <origin rpy="0 0 0" xyz="0 0 0"/>
      <geometry>
        <mesh filename="package://universal_robot/meshes/Link3.stl" scale="0.001 0.001 0.001"/>
      </geometry>
    </collision>
    <visual>
      <origin rpy="0 0 0" xyz="0 0 0"/>
      <geometry>
        <mesh filename="package://universal_robot/meshes/Link3.stl" scale="0.001 0.001 0.001"/>
      </geometry>
      <material name="Orange"/>
    </visual>
  </link>
  <joint name="q4" type="revolute">
    <axis xyz="0 1 0"/>
    <limit effort="1000" lower="-3.14" upper="3.14" velocity="0.5"/>
    <origin rpy="0 0 0" xyz="0.65625 0.0225 0"/>
    <parent link="link03"/>
    <child link="link04"/>
  </joint>
  <transmission name="trans_q4">
    <type>transmission_interface/SimpleTransmission</type>
    <joint name="q4">
      <hardwareInterface>hardware_interface/PositionJointInterface</hardwareInterface>
    </joint>
    <actuator name="motor_q4">
      <hardwareInterface>hardware_interface/PositionJointInterface</hardwareInterface>
      <mechanicalReduction>100</mechanicalReduction>
    </actuator>
  </transmission>
  <link name="link04">
    <inertial>
      <mass value="9.9"/>
      <origin rpy="0 0 0" xyz="0 0 0"/>
      <inertia ixx="17.71" ixy="0.209" ixz="-0.001" iyy="464.8" iyz="0" izz="467.7"/>
    </inertial>
    <collision>
      <origin rpy="0 0 0" xyz="0 0 0"/>
      <geometry>
        <mesh filename="package://universal_robot/meshes/Link4.stl" scale="0.001 0.001 0.001"/>
      </geometry>
    </collision>
    <visual>
      <origin rpy="0 0 0" xyz="0 0 0"/>
      <geometry>
        <mesh filename="package://universal_robot/meshes/Link4.stl" scale="0.001 0.001 0.001"/>
      </geometry>
      <material name="Orange"/>
    </visual>
  </link>
  <joint name="q5" type="revolute">
    <axis xyz="0 1 0"/>
    <limit effort="1000" lower="-3.14" upper="3.14" velocity="0.5"/>
    <origin rpy="0 0 0" xyz=" 0.531 -0.011475 0"/>
    <parent link="link04"/>
    <child link="link05"/>
  </joint>
  <transmission name="trans_q5">
    <type>transmission_interface/SimpleTransmission</type>
    <joint name="q5">
      <hardwareInterface>hardware_interface/PositionJointInterface</hardwareInterface>
    </joint>
    <actuator name="motor_q5">
      <hardwareInterface>hardware_interface/PositionJointInterface</hardwareInterface>
      <mechanicalReduction>100</mechanicalReduction>
    </actuator>
  </transmission>
  <link name="link05">
    <inertial>
      <mass value="2.38"/>
      <origin rpy="0 0 0" xyz="0 0 0"/>
      <inertia ixx="5.613" ixy="-0.8" ixz="0" iyy="6.205" iyz="0" izz="8.616"/>
    </inertial>
    <collision>
      <origin rpy="0 0 0" xyz="0 0 0"/>
      <geometry>
        <mesh filename="package://universal_robot/meshes/Link5.stl" scale="0.001 0.001 0.001"/>
      </geometry>
    </collision>
    <visual>
      <origin rpy="0 0 0" xyz="0 0 0"/>
      <geometry>
        <mesh filename="package://universal_robot/meshes/Link5.stl" scale="0.001 0.001 0.001"/>
      </geometry>
      <material name="Orange"/>
    </visual>
  </link>
  <joint name="q6" type="revolute">
    <axis xyz="1 0 0"/>
    <limit effort="1000" lower="-3.14" upper="3.14" velocity="0.5"/>
    <origin rpy="0 0 0" xyz="0.0985 0.1 0"/>
    <parent link="link05"/>
    <child link="link06"/>
  </joint>
  <transmission name="trans_q6">
    <type>transmission_interface/SimpleTransmission</type>
    <joint name="q6">
      <hardwareInterface>hardware_interface/PositionJointInterface</hardwareInterface>
    </joint>
    <actuator name="motor_q6">
      <hardwareInterface>hardware_interface/PositionJointInterface</hardwareInterface>
      <mechanicalReduction>100</mechanicalReduction>
    </actuator>
  </transmission>
  <link name="link06">
    <inertial>
      <mass value="1.75"/>
      <origin rpy="0 0 0" xyz="0 0 0"/>
      <inertia ixx="2.865" ixy="0.01" ixz="0" iyy="2.792" iyz="0" izz="3.318"/>
    </inertial>
    <collision>
      <origin rpy="0 0 0" xyz="0 0 0"/>
      <geometry>
        <mesh filename="package://universal_robot/meshes/Link6.stl" scale="0.001 0.001 0.001"/>
      </geometry>
    </collision>
    <visual>
      <origin rpy="0 0 0" xyz="0 0 0"/>
      <geometry>
        <mesh filename="package://universal_robot/meshes/Link6.stl" scale="0.001 0.001 0.001"/>
      </geometry>
      <material name="Orange"/>
    </visual>
  </link>
  <joint name="q7" type="revolute">
    <axis xyz="0 1 0"/>
    <limit effort="1000" lower="-3.14" upper="3.14" velocity="0.5"/>
    <origin rpy="0 0 0" xyz="0.0605 0.057 0"/>
    <parent link="link06"/>
    <child link="link07"/>
  </joint>
  <transmission name="trans_q7">
    <type>transmission_interface/SimpleTransmission</type>
    <joint name="q7">
      <hardwareInterface>hardware_interface/PositionJointInterface</hardwareInterface>
    </joint>
    <actuator name="motor_q7">
      <hardwareInterface>hardware_interface/PositionJointInterface</hardwareInterface>
      <mechanicalReduction>100</mechanicalReduction>
    </actuator>
  </transmission>
  <link name="link07">
    <inertial>
      <mass value="0.37"/>
      <origin rpy="0 0 0" xyz="0 0 0"/>
      <inertia ixx="0.2773" ixy="0" ixz="0" iyy="0.493" iyz="0" izz="0.2773"/>
    </inertial>
    <collision>
      <origin rpy="0 0 0" xyz="0 0 0"/>
      <geometry>
        <mesh filename="package://universal_robot/meshes/Link7.stl" scale="0.001 0.001 0.001"/>
      </geometry>
    </collision>
    <visual>
      <origin rpy="0 0 0" xyz="0 0 0"/>
      <geometry>
        <mesh filename="package://universal_robot/meshes/Link7.stl" scale="0.001 0.001 0.001"/>
      </geometry>
      <material name="Grey"/>
    </visual>
  </link>
  <joint name="q8" type="prismatic">
    <axis xyz="0 1 0"/>
    <limit effort="1000" lower="0" upper="0.1" velocity="0.5"/>
    <origin rpy="0 0 0" xyz="0 -0.09 0"/>
    <parent link="link07"/>
    <child link="linkef"/>
  </joint>
  <transmission name="trans_q8">
    <type>transmission_interface/SimpleTransmission</type>
    <joint name="q8">
      <hardwareInterface>hardware_interface/PositionJointInterface</hardwareInterface>
    </joint>
    <actuator name="motor_q8">
      <hardwareInterface>hardware_interface/PositionJointInterface</hardwareInterface>
      <mechanicalReduction>100</mechanicalReduction>
    </actuator>
  </transmission>
  <link name="linkef">
    <inertial>
      <mass value="1.69"/>
      <origin rpy="0 0 0" xyz="0 0 0"/>
      <inertia ixx="16.89" ixy="0" ixz="0" iyy="0.5042" iyz="-0.28" izz="16.89"/>
    </inertial>
    <collision>
      <origin rpy="0 0 0" xyz="0 0 0"/>
      <geometry>
        <mesh filename="package://universal_robot/meshes/Link_EF.stl" scale="0.001 0.001 0.001"/>
      </geometry>
    </collision>
    <visual>
      <origin rpy="0 0 0" xyz="0 0 0"/>
      <geometry>
        <mesh filename="package://universal_robot/meshes/Link_EF.stl" scale="0.001 0.001 0.001"/>
      </geometry>
      <material name="Grey"/>
    </visual>
  </link>
</robot>

